<robot name="picker">
    <link name="base_footprint"></link>
    <joint name="base_joint" type="fixed">
        <parent link="base_footprint" />
        <child link="base_link" />
        <origin xyz="0 0 0" rpy="0 0 0" />
    </joint>
    <link name="base_link">
        <visual>
            <origin xyz="0.53 -0.1 0.2" rpy="4.71238898038 1.57079632679 0" />
            <geometry>
                <!-- <box size="0.2 1.72 0.1" /> -->
                <mesh filename="file://meshes/link1.dae" />
            </geometry>
            <material name="base_link-material">
                <color rgba="0.6795424696265424 0.28314874041918053 0.6038273388475408 1" />
            </material>
        </visual>
        <collision>
            <origin xyz="0 0 0" rpy="0 0 0" />
            <geometry>
                <box size="0.2 1.72 0.1" />
            </geometry>
        </collision>
        <inertial>
            <origin xyz="0 0 0" rpy="0 0 0" />
            <mass value="1" />
            <inertia ixx="0.16666666666666666" ixy="0" ixz="0" iyy="0.16666666666666666" iyz="0"
                izz="0.16666666666666666" />
        </inertial>
    </link>
    <joint name="base_link_to_link2" type="prismatic">
        <parent link="base_link" />
        <child link="link2" />
        <origin xyz="0.47820843687512327 -0.7 0.16" rpy="0 0 0" />
        <axis xyz="0 1 0" />
        <limit effort="1000.0" lower="0" upper="1.3" velocity="1.2" />
    </joint>
    <link name="link2">
        <visual>
            <origin xyz="0 0.6 0.08" rpy="-1.57079632679 1.57079632679 00" />
            <geometry>
                <!-- <box size="1.18 0.1 0.2" /> -->
                <mesh filename="file://meshes/link2.dae" />
            </geometry>
            <material name="link2-material">
                <color rgba="0.054480276435339814 0.46778379610254284 0.14412847084818123 1" />
            </material>
        </visual>
        <collision>
            <origin xyz="0 0 0" rpy="0 0 0" />
            <geometry>
                <box size="1.18 0.1 0.2" />
            </geometry>
        </collision>
        <inertial>
            <origin xyz="0 0 0" rpy="0 0 0" />
            <mass value="1" />
            <inertia ixx="0.16666666666666666" ixy="0" ixz="0" iyy="0.16666666666666666" iyz="0"
                izz="0.16666666666666666" />
        </inertial>
    </link>
    <joint name="link2_to_link3_1" type="prismatic">
        <parent link="link2" />
        <child link="link3_1" />
        <origin xyz="0.40 0.08 0" rpy="0 0 0" />
        <axis xyz="-1 0 0" />
        <limit effort="1000.0" lower="0" upper="0.7" velocity="1.2" />
    </joint>
    <link name="link3_1">
        <visual>
            <origin xyz="0 0 0" rpy="0 0 0" />
            <!-- may need to uncomment for conversion -->
            <geometry>
                <box size="0.05 0.05 0.2" />
            </geometry>
            <material name="link3_1-material">
                <color rgba="0.4969329950515914 0.22696587349938613 0.12477181755144427 1" />
            </material>
        </visual>
        <collision>
            <origin xyz="0 0 0" rpy="0 0 0" />
            <geometry>
                <box size="0.05 0.05 0.2" />
            </geometry>
        </collision>
        <inertial>
            <origin xyz="0 0 0" rpy="0 0 0" />
            <mass value="1" />
            <inertia ixx="0.16666666666666666" ixy="0" ixz="0" iyy="0.16666666666666666" iyz="0"
                izz="0.16666666666666666" />
        </inertial>
    </link>
    <joint name="link3_1_to_link4_1" type="prismatic">
        <parent link="link3_1" />
        <child link="link4_1" />
        <origin xyz="0.001791563124876716 0.050000000000000044 0.33999999999999997" rpy="0 0 0" />
        <axis xyz="0 0 1" />
        <limit effort="1000.0" lower="-0.9" upper="0" velocity="1.2" />
    </joint>
    <link name="link4_1">
        <visual>
            <origin xyz="-0.38 0.47 -0.26" rpy="-1.57079632679 1.57079632679 0" />
            <geometry>
                <!-- <box size="0.05 0.05 1" /> -->
                <mesh filename="file://meshes/link3_1.dae" />
            </geometry>
            <material name="link4_1-material">
                <color rgba="0.5209955731953768 0.6375968739867731 0.13843161502267545 1" />
            </material>
        </visual>
        <collision>
            <origin xyz="0 0 0" rpy="0 0 0" />
            <geometry>
                <box size="0.05 0.05 1" />
            </geometry>
        </collision>
        <inertial>
            <origin xyz="0 0 0" rpy="0 0 0" />
            <mass value="1" />
            <inertia ixx="0.16666666666666666" ixy="0" ixz="0" iyy="0.16666666666666666" iyz="0"
                izz="0.16666666666666666" />
        </inertial>
    </link>
</robot>